<?xml version="1.0"?>
<robot name="platform">
    <link name="base_link">
        <visual>
            <geometry>
                <box size="0.1 0.1 0.1" />
            </geometry>
        </visual>
    </link>
    <link name="helipad_base_link">
        <visual>
            <geometry>
                <box size="0.001 0.001 0.001" />
            </geometry>
        </visual>
    </link>
    <link name="helipad_xrot_link">
        <visual>
            <geometry>
                <box size="0.001 0.001 0.001" />
            </geometry>
        </visual>
    </link>
    <link name="helipad_yrot_link">
        <inertial>
            <mass value="5" />
            <origin xyz="0 0 0" rpy="0 0 0" />
            <inertia ixx="1" ixy="0" ixz="0" iyy="1" iyz="0" izz="2" />
          </inertial>
        <visual>
            <geometry>
                 <box size="1.2 1.2 0.01"/>
            </geometry>
            <material name="black">
                <color rgba="0 0 0 1"/>
            </material>
        </visual>
        <collision>
            <geometry>
                 <box size="1.2 1.2 0.01"/>
            </geometry>
        </collision>
    </link>
    <link name="horizontal">
        <visual>
            <geometry>
                 <box size="1.2 0.05 0.01"/>
            </geometry>
            <material name="yellow">
                <color rgba="255 255 0 1"/>
            </material>
        </visual>
    </link>
    <link name="vertical">
        <visual>
            <geometry>
                 <box size="0.05 1.2 0.01"/>
            </geometry>
            <material name="yellow">
                <color rgba="255 255 0 1"/>
            </material>
        </visual>
    </link>
    <joint name="base_to_helipad_linear" type="prismatic">
        <parent link="base_link" />
        <child link="helipad_base_link" />
        <origin xyz="0.0 0.0 0.25" />
        <axis xyz="0.0 0.0 1.0" />
        <limit lower="-0.5" upper="0.5" effort="100" velocity="100"/>
        <dynamics damping="50"/>
    </joint>
    <joint name="base_to_helipad_xrot" type="revolute">
        <parent link="helipad_base_link" />
        <child link="helipad_xrot_link" />
        <origin xyz="0.0 0.0 0.25" />
        <axis xyz="1.0 0.0 0.0" />
        <limit lower="-0.35" upper="0.35" effort="100" velocity="100"/>
        <dynamics damping="70"/>
    </joint>
    <joint name="base_to_helipad_yrot" type="revolute">
        <parent link="helipad_xrot_link" />
        <child link="helipad_yrot_link" />
        <origin xyz="0.0 0.0 0.25" />
        <axis xyz="0.0 1.0 0.0" />
        <limit lower="-0.35" upper="0.35" effort="100" velocity="100"/>
        <dynamics damping="70"/>
    </joint>
    <joint name="helipad_to_horizontal" type="fixed">
        <parent link="helipad_yrot_link" />
        <child link="horizontal" />
        <origin xyz="0.0 0.0 0.0001" />
    </joint>
    <joint name="helipad_to_vertical" type="fixed">
        <parent link="helipad_yrot_link" />
        <child link="vertical" />
        <origin xyz="0.0 0.0 0.0001" />
    </joint>
</robot>